--------------------------------------------------------------------------------(Solver execution current time: 0.00021576881408691406)
[INFO] Input Seed : 6463343
--------------------------------------------------------------------------------(Solver execution current time: 0.00024890899658203125)
[INFO] Input time limit : 10
--------------------------------------------------------------------------------(Solver execution current time: 0.0002777576446533203)
[INFO] Command line arguments read with no errors.
--------------------------------------------------------------------------------(Solver execution current time: 0.004472255706787109)
[INFO] Algorithm execution time : 0.0051593780517578125
--------------------------------------------------------------------------------(Solver execution current time: 0.004905223846435547)
[ERROR]
An error has ocurred
Traceback (most recent call last):
  File "./solver/solver.py", line 189, in execute
    func_timeout(time_limit, run)
  File "/home/thuza/.local/lib/python3.8/site-packages/func_timeout/dafunc.py", line 108, in func_timeout
    raise_exception(exception)
  File "/home/thuza/.local/lib/python3.8/site-packages/func_timeout/py3_raise.py", line 7, in raise_exception
    raise exception[0] from None
  File "./solver/solver.py", line 95, in run
    read_input_file()
  File "./solver/solver.py", line 78, in read_input_file
    reader.read_input_file()
  File "/home/thuza/Desktop/vrp-solver/solver/src/instance_readers/Reader.py", line 86, in read_input_file
    self.read_specific_input(file_name)
  File "/home/thuza/Desktop/vrp-solver/solver/src/instance_readers/ReaderJsonDPDPTWLimitedFleet.py", line 36, in read_specific_input
    fleet_size = input_dict["fleet_size"]
KeyError: 'fleet_size'

--------------------------------------------------------------------------------